<?xml version="1.0" ?>
<!-- =================================================================================== -->
<!-- |    This document was autogenerated by xacro from /home/jordan/val_indigo/src/val_description/model/robots/pelvis_robot.xacro | -->
<!-- |    EDITING THIS FILE BY HAND IS NOT RECOMMENDED                                 | -->
<!-- =================================================================================== -->
<robot name="pelvisRobot" xmlns:xacro="http://ros.org/wiki/xacro">
  <gazebo>
    <plugin filename="libval_gazebo.so" name="SharedMemorySimInterfacePlugin">
      <robotNamespace>/val</robotNamespace>
      <updateRateHz>500.0</updateRateHz>
    </plugin>
  </gazebo>
    <!--<gazebo>-->
      <!--<joint name="fixed" type="revolute">-->
        <!--<parent>world</parent>-->
        <!--<child>pelvis</child>-->
        <!--<origin rpy="0 0 0" xyz="0 0 1"/>-->
        <!--<axis xyz="1 0 0"/>-->
      <!--</joint>-->
    <!--</gazebo>-->
  <gazebo>
      <joint name="fixed" type="revolute">
        <parent>world</parent>
        <child>fixedLink</child>
        <origin rpy="0 0 0" xyz="0 0 1"/>
        <axis xyz="1 0 0"/>
      </joint>
    </gazebo>
  <link name="fixedLink">
    <inertial>
      <mass value="8.22"/>
      <origin rpy="0 0 0" xyz="0.1 0.1 0.5"/>
      <inertia ixx="0.11866378" ixy="-0.000143482" ixz="0.003271293" iyy="0.097963425" iyz="0.002159545" izz="0.083854638"/>
    </inertial>
  </link>
  <joint name="rootJoint" type="revolute">
    <origin rpy="0.0 0.0 0.0" xyz="0 0 0"/>
    <axis xyz="0 1 0"/>
    <parent link="fixedLink"/>
    <child link="fixedLink2"/>
    <limit effort="0" lower="-10" upper="110" velocity="2"/>
  </joint>

  <link name="fixedLink2">
    <inertial>
      <mass value="8.22"/>
      <origin rpy="0 0 0" xyz="0.1 0.1 0.5"/>
      <inertia ixx="0.11866378" ixy="-0.000143482" ixz="0.003271293" iyy="0.097963425" iyz="0.002159545" izz="0.083854638"/>
    </inertial>
  </link>
  <joint name="fakeJoint2" type="revolute">
    <origin rpy="0.0 0.0 0.0" xyz="0 0 0"/>
    <axis xyz="0 1 0"/>
    <parent link="fixedLink"/>
    <child link="pelvis"/>
    <limit effort="0" lower="-10" upper="110" velocity="2"/>
  </joint>

  <link name="pelvis">
    <inertial>
      <mass value="8.22"/>
      <origin rpy="0 0 0" xyz="-0.00532 -0.003512 -0.0036"/>
      <inertia ixx="0.11866378" ixy="-0.000143482" ixz="0.003271293" iyy="0.097963425" iyz="0.002159545" izz="0.083854638"/>
    </inertial>
    <visual>
      <geometry>
        <mesh filename="package://val_description/model/meshes/pelvis/pelvis.dae"/>
      </geometry>
      <origin rpy="0.0 0.0 0.0" xyz="0.0 0.0 0.0"/>
    </visual>
    <collision>
      <geometry>
        <mesh filename="package://val_description/model/meshes/pelvis/pelvis.dae"/>
      </geometry>
      <origin rpy="0 0 0" xyz="0 0 0"/>
    </collision>
  </link>
  <link name="FakeImu_Frame">
    <!-- Virtual Link -->
    <inertial>
      <mass value="1e-07"/>
      <origin rpy="0 0 0" xyz="0 0 0"/>
      <inertia ixx="3.33333333333e-22" ixy="0.0" ixz="0.0" iyy="3.33333333333e-22" iyz="0.0" izz="5e-22"/>
    </inertial>
  </link>
  <joint name="FakeImu_Offset" type="fixed">
    <origin rpy="0 0 0" xyz="0 0 0"/>
    <axis xyz="0 0 1"/>
    <parent link="pelvis"/>
    <child link="FakeImu_Frame"/>
  </joint>
  <gazebo reference="FakeImu_Offset">
    <implicitSpringDamper>1</implicitSpringDamper>
  </gazebo>
  <gazebo>
    <plugin filename="libgazebo_ros_imu.so" name="imu_plugin_ros">
      <alwaysOn>true</alwaysOn>
      <bodyName>FakeImu_Frame</bodyName>
      <topicName>FakeImu/imu</topicName>
      <serviceName>FakeImu/imu_service</serviceName>
      <gaussianNoise>0.0</gaussianNoise>
      <updateRate>1</updateRate>
    </plugin>
  </gazebo>
  <gazebo reference="FakeImu_Frame">
    <sensor name="FakeImu" type="imu">
      <always_on>true</always_on>
      <pose>0 0 0 0 0 0</pose>
      <node name="/sensors/FakeIMU"/>
      <api name="simulated_imu_sensor::SimulatedImuSensor"/>
      <port name="none"/>
      <imu>
        <noise>
          <type>none</type>
          <rate>
            <mean>0</mean>
            <stddev>1e-6</stddev>
            <bias_mean>7.5e-06</bias_mean>
            <bias_stddev>8e-07</bias_stddev>
          </rate>
          <accel>
            <mean>0</mean>
            <stddev>1e-6</stddev>
            <bias_mean>1e-8</bias_mean>
            <bias_stddev>1e-8</bias_stddev>
          </accel>
        </noise>
      </imu>
    </sensor>
  </gazebo>
</robot>
